Loading gmp version 6.2.1
Loading mpfr version 3.1.6
Loading mpc version 1.1.0
Loading zlib-ng version 2.1.6
Loading gcc version 9.4.0
2025-05-05 03:14:54.854036: E external/local_xla/xla/stream_executor/cuda/cuda_fft.cc:467] Unable to register cuFFT factory: Attempting to register factory for plugin cuFFT when one has already been registered
WARNING: All log messages before absl::InitializeLog() is called are written to STDERR
E0000 00:00:1746414894.912905  442369 cuda_dnn.cc:8579] Unable to register cuDNN factory: Attempting to register factory for plugin cuDNN when one has already been registered
E0000 00:00:1746414894.927391  442369 cuda_blas.cc:1407] Unable to register cuBLAS factory: Attempting to register factory for plugin cuBLAS when one has already been registered
W0000 00:00:1746414895.029980  442369 computation_placer.cc:177] computation placer already registered. Please check linkage and avoid linking the same target more than once.
W0000 00:00:1746414895.030034  442369 computation_placer.cc:177] computation placer already registered. Please check linkage and avoid linking the same target more than once.
W0000 00:00:1746414895.030042  442369 computation_placer.cc:177] computation placer already registered. Please check linkage and avoid linking the same target more than once.
W0000 00:00:1746414895.030047  442369 computation_placer.cc:177] computation placer already registered. Please check linkage and avoid linking the same target more than once.
2025-05-05 03:14:55.072681: I tensorflow/core/platform/cpu_feature_guard.cc:210] This TensorFlow binary is optimized to use available CPU instructions in performance-critical operations.
To enable the following instructions: AVX2 FMA, in other operations, rebuild TensorFlow with the appropriate compiler flags.
Traceback (most recent call last):
  File "/work/pi_jaimedavila_umass_edu/asharda_umass_edu/test_LLM/lib/python3.12/site-packages/huggingface_hub/utils/_http.py", line 409, in hf_raise_for_status
    response.raise_for_status()
  File "/work/pi_jaimedavila_umass_edu/asharda_umass_edu/test_LLM/lib/python3.12/site-packages/requests/models.py", line 1024, in raise_for_status
    raise HTTPError(http_error_msg, response=self)
requests.exceptions.HTTPError: 401 Client Error: Unauthorized for url: https://huggingface.co/meta-llama/Llama-2-13b-chat-hf/resolve/main/config.json

The above exception was the direct cause of the following exception:

Traceback (most recent call last):
  File "/work/pi_jaimedavila_umass_edu/asharda_umass_edu/test_LLM/lib/python3.12/site-packages/transformers/utils/hub.py", line 342, in cached_file
    resolved_file = hf_hub_download(
                    ^^^^^^^^^^^^^^^^
  File "/work/pi_jaimedavila_umass_edu/asharda_umass_edu/test_LLM/lib/python3.12/site-packages/huggingface_hub/utils/_validators.py", line 114, in _inner_fn
    return fn(*args, **kwargs)
           ^^^^^^^^^^^^^^^^^^^
  File "/work/pi_jaimedavila_umass_edu/asharda_umass_edu/test_LLM/lib/python3.12/site-packages/huggingface_hub/file_download.py", line 862, in hf_hub_download
    return _hf_hub_download_to_cache_dir(
           ^^^^^^^^^^^^^^^^^^^^^^^^^^^^^^
  File "/work/pi_jaimedavila_umass_edu/asharda_umass_edu/test_LLM/lib/python3.12/site-packages/huggingface_hub/file_download.py", line 969, in _hf_hub_download_to_cache_dir
    _raise_on_head_call_error(head_call_error, force_download, local_files_only)
  File "/work/pi_jaimedavila_umass_edu/asharda_umass_edu/test_LLM/lib/python3.12/site-packages/huggingface_hub/file_download.py", line 1486, in _raise_on_head_call_error
    raise head_call_error
  File "/work/pi_jaimedavila_umass_edu/asharda_umass_edu/test_LLM/lib/python3.12/site-packages/huggingface_hub/file_download.py", line 1376, in _get_metadata_or_catch_error
    metadata = get_hf_file_metadata(
               ^^^^^^^^^^^^^^^^^^^^^
  File "/work/pi_jaimedavila_umass_edu/asharda_umass_edu/test_LLM/lib/python3.12/site-packages/huggingface_hub/utils/_validators.py", line 114, in _inner_fn
    return fn(*args, **kwargs)
           ^^^^^^^^^^^^^^^^^^^
  File "/work/pi_jaimedavila_umass_edu/asharda_umass_edu/test_LLM/lib/python3.12/site-packages/huggingface_hub/file_download.py", line 1296, in get_hf_file_metadata
    r = _request_wrapper(
        ^^^^^^^^^^^^^^^^^
  File "/work/pi_jaimedavila_umass_edu/asharda_umass_edu/test_LLM/lib/python3.12/site-packages/huggingface_hub/file_download.py", line 280, in _request_wrapper
    response = _request_wrapper(
               ^^^^^^^^^^^^^^^^^
  File "/work/pi_jaimedavila_umass_edu/asharda_umass_edu/test_LLM/lib/python3.12/site-packages/huggingface_hub/file_download.py", line 304, in _request_wrapper
    hf_raise_for_status(response)
  File "/work/pi_jaimedavila_umass_edu/asharda_umass_edu/test_LLM/lib/python3.12/site-packages/huggingface_hub/utils/_http.py", line 426, in hf_raise_for_status
    raise _format(GatedRepoError, message, response) from e
huggingface_hub.errors.GatedRepoError: 401 Client Error. (Request ID: Root=1-68182d49-03168a7b0683586a27a42bab;fa8a8a5b-8343-4aa5-9729-c7a2d96edf2a)

Cannot access gated repo for url https://huggingface.co/meta-llama/Llama-2-13b-chat-hf/resolve/main/config.json.
Access to model meta-llama/Llama-2-13b-chat-hf is restricted. You must have access to it and be authenticated to access it. Please log in.

The above exception was the direct cause of the following exception:

Traceback (most recent call last):
  File "/work/pi_jaimedavila_umass_edu/asharda_umass_edu/LLM_scripts/llama2_7b/runTrained.py", line 31, in <module>
    base_model = AutoModelForCausalLM.from_pretrained(
                 ^^^^^^^^^^^^^^^^^^^^^^^^^^^^^^^^^^^^^
  File "/work/pi_jaimedavila_umass_edu/asharda_umass_edu/test_LLM/lib/python3.12/site-packages/transformers/models/auto/auto_factory.py", line 526, in from_pretrained
    config, kwargs = AutoConfig.from_pretrained(
                     ^^^^^^^^^^^^^^^^^^^^^^^^^^^
  File "/work/pi_jaimedavila_umass_edu/asharda_umass_edu/test_LLM/lib/python3.12/site-packages/transformers/models/auto/configuration_auto.py", line 1075, in from_pretrained
    config_dict, unused_kwargs = PretrainedConfig.get_config_dict(pretrained_model_name_or_path, **kwargs)
                                 ^^^^^^^^^^^^^^^^^^^^^^^^^^^^^^^^^^^^^^^^^^^^^^^^^^^^^^^^^^^^^^^^^^^^^^^^^
  File "/work/pi_jaimedavila_umass_edu/asharda_umass_edu/test_LLM/lib/python3.12/site-packages/transformers/configuration_utils.py", line 594, in get_config_dict
    config_dict, kwargs = cls._get_config_dict(pretrained_model_name_or_path, **kwargs)
                          ^^^^^^^^^^^^^^^^^^^^^^^^^^^^^^^^^^^^^^^^^^^^^^^^^^^^^^^^^^^^^
  File "/work/pi_jaimedavila_umass_edu/asharda_umass_edu/test_LLM/lib/python3.12/site-packages/transformers/configuration_utils.py", line 653, in _get_config_dict
    resolved_config_file = cached_file(
                           ^^^^^^^^^^^^
  File "/work/pi_jaimedavila_umass_edu/asharda_umass_edu/test_LLM/lib/python3.12/site-packages/transformers/utils/hub.py", line 360, in cached_file
    raise EnvironmentError(
OSError: You are trying to access a gated repo.
Make sure to have access to it at https://huggingface.co/meta-llama/Llama-2-13b-chat-hf.
401 Client Error. (Request ID: Root=1-68182d49-03168a7b0683586a27a42bab;fa8a8a5b-8343-4aa5-9729-c7a2d96edf2a)

Cannot access gated repo for url https://huggingface.co/meta-llama/Llama-2-13b-chat-hf/resolve/main/config.json.
Access to model meta-llama/Llama-2-13b-chat-hf is restricted. You must have access to it and be authenticated to access it. Please log in.
